[2022-08-12 20:28:29,745] {taskinstance.py:1159} INFO - Dependencies all met for <TaskInstance: ETL_Raízen.create_pet_table manual__2022-08-12T20:27:43.337796+00:00 [queued]>
[2022-08-12 20:28:29,757] {taskinstance.py:1159} INFO - Dependencies all met for <TaskInstance: ETL_Raízen.create_pet_table manual__2022-08-12T20:27:43.337796+00:00 [queued]>
[2022-08-12 20:28:29,758] {taskinstance.py:1356} INFO - 
--------------------------------------------------------------------------------
[2022-08-12 20:28:29,759] {taskinstance.py:1357} INFO - Starting attempt 1 of 1
[2022-08-12 20:28:29,760] {taskinstance.py:1358} INFO - 
--------------------------------------------------------------------------------
[2022-08-12 20:28:29,777] {taskinstance.py:1377} INFO - Executing <Task(PostgresOperator): create_pet_table> on 2022-08-12 20:27:43.337796+00:00
[2022-08-12 20:28:29,783] {standard_task_runner.py:52} INFO - Started process 989 to run task
[2022-08-12 20:28:29,786] {standard_task_runner.py:79} INFO - Running: ['***', 'tasks', 'run', 'ETL_Raízen', 'create_pet_table', 'manual__2022-08-12T20:27:43.337796+00:00', '--job-id', '227', '--raw', '--subdir', 'DAGS_FOLDER/ETL_Raizen.py', '--cfg-path', '/tmp/tmp7e5g5dpc', '--error-file', '/tmp/tmpmkafu7rq']
[2022-08-12 20:28:29,788] {standard_task_runner.py:80} INFO - Job 227: Subtask create_pet_table
[2022-08-12 20:28:29,868] {task_command.py:369} INFO - Running <TaskInstance: ETL_Raízen.create_pet_table manual__2022-08-12T20:27:43.337796+00:00 [running]> on host 4bbb34367c41
[2022-08-12 20:28:29,984] {taskinstance.py:1571} INFO - Exporting the following env vars:
AIRFLOW_CTX_DAG_OWNER=***
AIRFLOW_CTX_DAG_ID=ETL_Raízen
AIRFLOW_CTX_TASK_ID=create_pet_table
AIRFLOW_CTX_EXECUTION_DATE=2022-08-12T20:27:43.337796+00:00
AIRFLOW_CTX_TRY_NUMBER=1
AIRFLOW_CTX_DAG_RUN_ID=manual__2022-08-12T20:27:43.337796+00:00
[2022-08-12 20:28:30,029] {taskinstance.py:1889} ERROR - Task failed with exception
Traceback (most recent call last):
  File "/home/airflow/.local/lib/python3.7/site-packages/airflow/providers/postgres/operators/postgres.py", line 92, in execute
    self.hook.run(self.sql, self.autocommit, parameters=self.parameters)
  File "/home/airflow/.local/lib/python3.7/site-packages/airflow/hooks/dbapi.py", line 181, in run
    with closing(self.get_conn()) as conn:
  File "/home/airflow/.local/lib/python3.7/site-packages/airflow/providers/postgres/hooks/postgres.py", line 86, in get_conn
    conn = deepcopy(self.connection or self.get_connection(conn_id))
  File "/home/airflow/.local/lib/python3.7/site-packages/airflow/hooks/base.py", line 67, in get_connection
    conn = Connection.get_connection_from_secrets(conn_id)
  File "/home/airflow/.local/lib/python3.7/site-packages/airflow/models/connection.py", line 430, in get_connection_from_secrets
    raise AirflowNotFoundException(f"The conn_id `{conn_id}` isn't defined")
airflow.exceptions.AirflowNotFoundException: The conn_id `postgres_default` isn't defined
[2022-08-12 20:28:30,037] {taskinstance.py:1400} INFO - Marking task as FAILED. dag_id=ETL_Raízen, task_id=create_pet_table, execution_date=20220812T202743, start_date=20220812T202829, end_date=20220812T202830
[2022-08-12 20:28:30,064] {standard_task_runner.py:97} ERROR - Failed to execute job 227 for task create_pet_table (The conn_id `postgres_default` isn't defined; 989)
[2022-08-12 20:28:30,080] {local_task_job.py:156} INFO - Task exited with return code 1
[2022-08-12 20:28:30,147] {local_task_job.py:273} INFO - 0 downstream tasks scheduled from follow-on schedule check
