[2022-08-12 21:19:00,608] {taskinstance.py:1159} INFO - Dependencies all met for <TaskInstance: ETL_Raízen.create_table_sqlite manual__2022-08-12T21:18:19.980399+00:00 [queued]>
[2022-08-12 21:19:00,629] {taskinstance.py:1159} INFO - Dependencies all met for <TaskInstance: ETL_Raízen.create_table_sqlite manual__2022-08-12T21:18:19.980399+00:00 [queued]>
[2022-08-12 21:19:00,630] {taskinstance.py:1356} INFO - 
--------------------------------------------------------------------------------
[2022-08-12 21:19:00,631] {taskinstance.py:1357} INFO - Starting attempt 1 of 1
[2022-08-12 21:19:00,632] {taskinstance.py:1358} INFO - 
--------------------------------------------------------------------------------
[2022-08-12 21:19:00,655] {taskinstance.py:1377} INFO - Executing <Task(SqliteOperator): create_table_sqlite> on 2022-08-12 21:18:19.980399+00:00
[2022-08-12 21:19:00,662] {standard_task_runner.py:52} INFO - Started process 3610 to run task
[2022-08-12 21:19:00,666] {standard_task_runner.py:79} INFO - Running: ['***', 'tasks', 'run', 'ETL_Raízen', 'create_table_sqlite', 'manual__2022-08-12T21:18:19.980399+00:00', '--job-id', '242', '--raw', '--subdir', 'DAGS_FOLDER/ETL_Raizen.py', '--cfg-path', '/tmp/tmpvdteldii', '--error-file', '/tmp/tmp7473fm5t']
[2022-08-12 21:19:00,669] {standard_task_runner.py:80} INFO - Job 242: Subtask create_table_sqlite
[2022-08-12 21:19:00,804] {task_command.py:369} INFO - Running <TaskInstance: ETL_Raízen.create_table_sqlite manual__2022-08-12T21:18:19.980399+00:00 [running]> on host 4bbb34367c41
[2022-08-12 21:19:00,935] {taskinstance.py:1571} INFO - Exporting the following env vars:
AIRFLOW_CTX_DAG_OWNER=***
AIRFLOW_CTX_DAG_ID=ETL_Raízen
AIRFLOW_CTX_TASK_ID=create_table_sqlite
AIRFLOW_CTX_EXECUTION_DATE=2022-08-12T21:18:19.980399+00:00
AIRFLOW_CTX_TRY_NUMBER=1
AIRFLOW_CTX_DAG_RUN_ID=manual__2022-08-12T21:18:19.980399+00:00
[2022-08-12 21:19:00,936] {sqlite.py:59} INFO - Executing: 
        CREATE TABLE Customers (
            customer_id INT PRIMARY KEY,
            first_name TEXT,
            last_name TEXT
        );
        
[2022-08-12 21:19:00,962] {taskinstance.py:1889} ERROR - Task failed with exception
Traceback (most recent call last):
  File "/home/airflow/.local/lib/python3.7/site-packages/airflow/providers/sqlite/operators/sqlite.py", line 61, in execute
    hook.run(self.sql, parameters=self.parameters)
  File "/home/airflow/.local/lib/python3.7/site-packages/airflow/hooks/dbapi.py", line 181, in run
    with closing(self.get_conn()) as conn:
  File "/home/airflow/.local/lib/python3.7/site-packages/airflow/providers/sqlite/hooks/sqlite.py", line 35, in get_conn
    airflow_conn = self.get_connection(conn_id)
  File "/home/airflow/.local/lib/python3.7/site-packages/airflow/hooks/base.py", line 67, in get_connection
    conn = Connection.get_connection_from_secrets(conn_id)
  File "/home/airflow/.local/lib/python3.7/site-packages/airflow/models/connection.py", line 430, in get_connection_from_secrets
    raise AirflowNotFoundException(f"The conn_id `{conn_id}` isn't defined")
airflow.exceptions.AirflowNotFoundException: The conn_id `sqlite_default` isn't defined
[2022-08-12 21:19:00,971] {taskinstance.py:1400} INFO - Marking task as FAILED. dag_id=ETL_Raízen, task_id=create_table_sqlite, execution_date=20220812T211819, start_date=20220812T211900, end_date=20220812T211900
[2022-08-12 21:19:00,988] {standard_task_runner.py:97} ERROR - Failed to execute job 242 for task create_table_sqlite (The conn_id `sqlite_default` isn't defined; 3610)
[2022-08-12 21:19:01,001] {local_task_job.py:156} INFO - Task exited with return code 1
[2022-08-12 21:19:01,040] {local_task_job.py:273} INFO - 0 downstream tasks scheduled from follow-on schedule check
